Workbook

Sheet CRES
A1: 2024 Actuals | B1: Jul 2024 | C1: Aug 2024 | D1: Sep 2024 | E1: Oct 2024 | F1: Nov 2024 | G1: Dec 2024 | H1: Jan 2025 | I1: Feb 2025 | J1: Mar 2025 | K1: Apr 2025 | L1: May 2025 | M1: Jun 2025 | N1: YTD
A2: Property Asking Rent | B2: 271.161 | C2: 271.161 | D2: 236.61 | E2: 235.91 | F2: 236.41 | G2: 236.295 | H2: 235.911 | I2: 235.895 | J2: 235.45 | K2: 235.014 | L2: 234.0793 | M2: 234.33196 | N2: 2898.2283
A3: Loss to lease | B3: -52.711 | C3: -52.58 | D3: -15.80087 | E3: -16.69427 | F3: -15.46522 | G3: -15.87041 | H3: -15.37974 | I3: -15.43153 | J3: -15.36058 | K3: -14.87067 | L3: -14.57557 | M3: -14.74146 | N3: -259.48132
A4: Gross Scheduled Rent | B4: 218.45 | C4: 218.581 | D4: 220.80913 | E4: 219.21573 | F4: 220.94478 | G4: 220.42459 | H4: 220.53126 | I4: 220.46347 | J4: 220.08942 | K4: 220.14333 | L4: 219.50373 | M4: 219.5905 | N4: 2638.7469
A5: Vacancy | B5: -13.7097 | C5: -12.02063 | D5: -15.93635 | E5: -19.86242 | F5: -18.00432 | G5: -21.63113 | H5: -21.85842 | I5: -27.98297 | J5: -24.76219 | K5: -24.46553 | L5: -27.11695 | M5: -27.68306 | N5: -255.03367
A6: Non Revenue Units | B6: -1.732 | C6: -1.732 | D6: -1.565 | E6: -1.565 | F6: -2.03995 | G6: -2.1845 | H6: -2.1845 | I6: -2.1845 | J6: -2.1845 | K6: -2.1845 | L6: -2.1845 | M6: -2.1845 | N6: -23.92545
A7: Concessions | B7: -0.5333 | C7: -0.1599 | D7: -4.69872 | E7: -1.68635 | F7: -1.1599 | G7: -3.1599 | H7: -3.2599 | I7: -1.4599 | J7: -1.9599 | K7: -4.4229 | L7: -3.1663 | M7: -7.42739 | N7: -33.09436
A8: Delinquency | B8: -23.19915 | C8: -7.63524 | D8: -5.76954 | E8: -1.79466 | F8: -15.75804 | G8: -10.16156 | H8: -15.78407 | I8: -2.39172 | J8: -8.47726 | K8: -4.35736 | L8: -9.7091 | M8: -3.86133 | N8: -108.89903
A9: Effective Rental Income | B9: 179.27585 | C9: 197.03323 | D9: 192.83952 | E9: 194.3073 | F9: 183.98257 | G9: 183.2875 | H9: 177.44437 | I9: 186.44438 | J9: 182.70557 | K9: 184.71304 | L9: 177.32688 | M9: 178.43422 | N9: 2217.7944
A10: Parking Garage Income | B10: 0 | C10: 0 | D10: 0 | E10: 0 | F10: 0 | G10: 0 | H10: 0 | I10: 0 | J10: 0 | K10: 0 | L10: 0 | M10: 0 | N10: 0
A11: Utility Income | B11: 6.79827 | C11: 6.37379 | D11: 4.84895 | E11: 5.30191 | F11: 5.34961 | G11: 9.51241 | H11: 9.14551 | I11: 10.34277 | J11: 7.56977 | K11: 8.21454 | L11: 7.76315 | M11: 8.08883 | N11: 89.30951
A12: Other - Income | B12: 19.95066 | C12: 18.48254 | D12: 7.5554 | E12: 9.15565 | F12: 11.65817 | G12: 17.317 | H12: 11.02487 | I12: 11.23292 | J12: 25.01947 | K12: 16.48196 | L12: 19.31162 | M12: 10.04436 | N12: 177.23462
A13: Total Other Income | B13: 26.74893 | C13: 24.85633 | D13: 12.40435 | E13: 14.45756 | F13: 17.00778 | G13: 26.82941 | H13: 20.17038 | I13: 21.57569 | J13: 32.58924 | K13: 24.6965 | L13: 27.07477 | M13: 18.13319 | N13: 266.54413
A14: Net Eff. Gross Income | B14: 206.02478 | C14: 221.88956 | D14: 205.24387 | E14: 208.76486 | F14: 200.99035 | G14: 210.11691 | H14: 197.61475 | I14: 208.02007 | J14: 215.29481 | K14: 209.40954 | L14: 204.40165 | M14: 196.56741 | N14: 2484.3386
B16: Jul 2024 | C16: Aug 2024 | D16: Sep 2024 | E16: Oct 2024 | F16: Nov 2024 | G16: Dec 2024 | H16: Jan 2025 | I16: Feb 2025 | J16: Mar 2025 | K16: Apr 2025 | L16: May 2025 | M16: Jun 2025 | N16: YTD
A17: General & Admin. | B17: -9.55162 | C17: -6.38157 | D17: -6.15476 | E17: -1.10669 | F17: -2.859 | G17: -5.57187 | H17: -1.72641 | I17: -7.63021 | J17: -23.41802 | K17: -4.83545 | L17: 20.72103 | M17: -5.40826 | N17: -53.92283
A18: Management Fee | B18: -6.43959 | C18: -7.81744 | D18: -10.89911 | E18: -7.533 | F18: -13.79983 | G18: -7.5 | H18: -7.5 | I18: -7.5 | J18: -7.5 | K18: -7.5 | L18: -7.5 | M18: -7.5 | N18: -98.98897
A19: Payroll | B19: -27.55898 | C19: -13.43476 | D19: -29.36487 | E19: -27.81409 | F19: -32.08065 | G19: -24.22299 | H19: -29.51785 | I19: -23.43926 | J19: -23.41582 | K19: -28.49068 | L19: -23.47187 | M19: -26.01337 | N19: -308.82519
A20: Insurance | B20: -5.45225 | C20: -5.45225 | D20: -9.18009 | E20: -9.18009 | F20: -9.18009 | G20: -9.68009 | H20: -9.18009 | I20: -9.18009 | J20: -9.18009 | K20: -9.18009 | L20: -9.18009 | M20: -9.18009 | N20: -103.2054
A21: Property Taxes | B21: -31.337 | C21: -31.337 | D21: -31.337 | E21: -31.337 | F21: -31.75919 | G21: -31.42691 | H21: -31.337 | I21: -31.337 | J21: -31.337 | K21: -31.337 | L21: -31.50121 | M21: -31.337 | N21: -376.72031
A22: Leasing & Marketing | B22: -5.23631 | C22: -3.85965 | D22: -0.48817 | E22: -3.61937 | F22: -5.94748 | G22: -11.67756 | H22: -3.71905 | I22: -5.67871 | J22: -5.37941 | K22: -4.88472 | L22: -8.14604 | M22: -6.72848 | N22: -65.36495
A23: Professional fees | B23: 0 | C23: 0 | D23: 0 | E23: 0 | F23: 0 | G23: 0 | H23: 0 | I23: 0 | J23: 0 | K23: 0 | L23: 0 | M23: 0 | N23: 0
A24: Landscaping | B24: -2.55908 | C24: -2.22644 | D24: -2.2 | E24: -2.56728 | F24: -8.37 | G24: -4.16015 | H24: -4.80056 | I24: -2.48649 | J24: -3.05373 | K24: -4.33914 | L24: -2.88779 | M24: -2.93596 | N24: -42.58662
A25: Security & Life Safety | B25: 0.09988 | C25: 0 | D25: 0 | E25: 0 | F25: 0 | G25: 0 | H25: 0 | I25: -4.75184 | J25: -0.34383 | K25: -0.52383 | L25: -0.34383 | M25: -3.00783 | N25: -8.87128
A26: Repairs & Maintenance | B26: -4.38872 | C26: -2.72555 | D26: -4.4206 | E26: -3.21349 | F26: -12.28809 | G26: -5.95662 | H26: -2.05406 | I26: -0.13437 | J26: -3.84569 | K26: -7.00491 | L26: -2.95149 | M26: -3.74404 | N26: -52.72763
A27: Unit T/O Refurbishment | B27: -5.72101 | C27: -2.745 | D27: -3.51143 | E27: -8.26492 | F27: -7.23099 | G27: -7.16533 | H27: -5.50371 | I27: -2.91955 | J27: -5.81329 | K27: -6.57544 | L27: -0.73 | M27: -1.7169 | N27: -57.89757
A28: Utilities | B28: -9.95882 | C28: -4.47982 | D28: -6.75211 | E28: -6.62676 | F28: -10.38538 | G28: -11.54114 | H28: -20.61163 | I28: -10.70401 | J28: -9.31124 | K28: -13.42028 | L28: -11.41003 | M28: -7.96649 | N28: -123.16771
... A32: Total Expense | B32: -113.48879 | C32: -78.61252 | D32: -107.70918 | E32: -106.17531 | F32: -139.10122 | G32: -127.09901 | H32: -120.94004 | I32: -105.19408 | J32: -126.64812 | K32: -122.47535 | L32: -82.29504 | M32: -110.15208 | N32: -1339.8907
B34: Jul 2024 | C34: Aug 2024 | D34: Sep 2024 | E34: Oct 2024 | F34: Nov 2024 | G34: Dec 2024 | H34: Jan 2025 | I34: Feb 2025 | J34: Mar 2025 | K34: Apr 2025 | L34: May 2025 | M34: Jun 2025 | N34: YTD
A35: EBITDA (NOI) | B35: 92.53599 | C35: 143.27704 | D35: 97.53469 | E35: 102.58955 | F35: 61.88913 | G35: 83.0179 | H35: 76.67471 | I35: 102.82599 | J35: 88.64669 | K35: 86.93419 | L35: 122.10661 | M35: 86.41533 | N35: 1144.4478
B36: Yes | C36: Yes | D36: Yes | E36: Yes | F36: Yes | G36: Yes | H36: Yes | I36: Yes | J36: Yes | K36: Yes | L36: Yes | M36: Yes
B37: Jul 2024 | C37: Aug 2024 | D37: Sep 2024 | E37: Oct 2024 | F37: Nov 2024 | G37: Dec 2024 | H37: Jan 2025 | I37: Feb 2025 | J37: Mar 2025 | K37: Apr 2025 | L37: May 2025 | M37: Jun 2025 | N37: YTD
A38: Repl. Reserve Fund | B38: -5.00473 | C38: -2.61006 | D38: -4.6 | E38: 0 | F38: -1.73547 | G38: 65.48008 | H38: -2.32565 | I38: -5.78282 | J38: -11.1821 | K38: -9.52209 | L38: -45.08336 | M38: -44.92517 | N38: -67.29137
A39: State Franchise Fee | B39: 0 | C39: 0 | D39: 0 | E39: 0 | F39: 0 | G39: 0 | H39: 0 | I39: 0 | J39: 0 | K39: 0 | L39: 0 | M39: 0 | N39: 0
A40: Partnership Professional Fees | B40: -1.21 | C40: -1.62809 | D40: -3.96605 | E40: -1.2185 | F40: -1.53198 | G40: -2.02935 | H40: -7.12985 | I40: -13.49 | J40: -20.4864 | K40: -3.95001 | L40: -16.05901 | M40: -1.47501 | N40: -74.17425
A41: Asset Management Fees | B41: -3.39911 | C41: -3.32831 | D41: -3.12958 | E41: -3.23487 | F41: -3.04756 | G41: -3.17406 | H41: -3.09461 | I41: -2.85558 | J41: -3.24529 | K41: -3.18311 | L41: -3.14905 | M41: -2.89211 | N41: -37.73324
A42: Debt Service | B42: -163.37724 | C42: -163.31857 | D42: -152.88809 | E42: -158.75899 | F42: -150.2879 | G42: -150.94259 | H42: -149.07327 | I42: -134.73959 | J42: -106.44333 | K42: -96.90521 | L42: -103.36534 | M42: -96.52155 | N42: -1626.6217
A43: Other - Below Line | B43: 0 | C43: 0 | D43: 0 | E43: 0 | F43: 0 | G43: 0 | H43: 0 | I43: 0 | J43: 0 | K43: 0 | L43: 0 | M43: 0 | N43: 0
A44: Total Below Line | B44: -172.99108 | C44: -170.88503 | D44: -164.58372 | E44: -163.21236 | F44: -156.60291 | G44: -90.66592 | H44: -161.62338 | I44: -156.86799 | J44: -141.35712 | K44: -113.56042 | L44: -167.65676 | M44: -145.81384 | N44: -1805.8205
A45: Renovations | B45: 0 | C45: 0 | D45: 0 | E45: 0 | F45: 0 | G45: 0 | H45: 0 | I45: 0 | J45: 0 | K45: 0 | L45: 0 | M45: 0 | N45: 0
...

Sheet Altamonte - Variance
A1: Las Palmas (693wymor)
A2: Budget Comparison
A3: Period = Mar 2024
A4: Book = Accrual ; Tree = ysi_is
C5: PTD Actual | D5: PTD Budget | E5: Variance | F5: % Var | G5: YTD Actual | H5: YTD Budget | I5: Variance | J5: % Var | K5: Annual
A7: 4000-0000 | B7: NET INCOME
A9: 4001-0000 | B9: OPERATING INCOME
A11: 4004-0000 | B11: REVENUE
A13: 4010-0000 | B13: MONTHLY RENT
A14: 4010-0010 | B14: Gross Potential Rent | C14: 378750 | D14: 375600 | E14: 3150 | F14: 0.84 | G14: 1133476 | H14: 1126800 | I14: 6676 | J14: 0.59 | K14: 4507200
A15: 4013-0000 | B15: Gain - Loss to Lease | C15: -3703 | D15: 2457.56 | E15: -6160.56 | F15: -250.68 | G15: -8654 | H15: 3529.6 | I15: -12183.6 | J15: -345.18 | K15: 68308.84
A17: 4019-9999 | B17: TOTAL MONTHLY RENT | C17: 375047 | D17: 378057.56 | E17: -3010.56 | F17: -0.8 | G17: 1124822 | H17: 1130329.6 | I17: -5507.6 | J17: -0.49 | K17: 4575508.8
A19: 4020-0000 | B19: RENTAL ADJUSTMENTS
A20: 4021-0000 | B20: Less: Concessions | C20: -10538 | D20: -1125 | E20: -9413 | F20: -836.71 | G20: -43564.24 | H20: -4673.07 | I20: -38891.17 | J20: -832.24 | K20: -19298.03
A21: 4022-0000 | B21: Less: Vacancies | C21: -54168.3 | D21: -41586.33 | E21: -12581.97 | F21: -30.26 | G21: -209656.4 | H21: -131858.97 | I21: -77797.43 | J21: -59 | K21: -414842.21
A22: 4023-0000 | B22: Less: Employee Units | C22: -1999 | D22: -450 | E22: -1549 | F22: -344.22 | G22: -2303.37 | H22: -1350 | I22: -953.37 | J22: -70.62 | K22: -5400
A23: 4025-0000 | B23: Less: Model Unit | C23: -1175 | D23: -1369 | E23: 194 | F23: 14.17 | G23: -4519.52 | H23: -4069 | I23: -450.52 | J23: -11.07 | K23: -16390
A24: 4026-0000 | B24: Less: Non Revenue Generating Units | C24: -1700 | D24: 0 | E24: -1700 | F24: N/A | G24: -5100 | H24: 0 | I24: -5100 | J24: N/A | K24: 0
A25: 4027-0000 | B25: Less: Bad Debt-Write Offs | C25: -14935.52 | D25: -20188.27 | E25: 5252.75 | F25: 26.02 | G25: 18363.49 | H25: -63218.23 | I25: 81581.72 | J25: 129.05 | K25: -189008.51
A27: 4039-9999 | B27: TOTAL RENTAL ADJUSTMENTS | C27: -84515.82 | D27: -64718.6 | E27: -19797.22 | F27: -30.59 | G27: -246780.04 | H27: -205169.27 | I27: -41610.77 | J27: -20.28 | K27: -644938.75
A29: 4200-0000 | B29: OTHER RENTAL INCOME
A30: 4201-0000 | B30: Utilities - RUBS - Water-Sewer | C30: 9136.03 | D30: 8141.64 | E30: 994.39 | F30: 12.21 | G30: 25269.66 | H30: 24424.92 | I30: 844.74 | J30: 3.46 | K30: 97699.68
A31: 4202-0000 | B31: Utilities - RUBS - Electric | C31: 546.84 | D31: 549.23 | E31: -2.39 | F31: -0.44 | G31: 2233.02 | H31: 1647.69 | I31: 585.33 | J31: 35.52 | K31: 6590.76
A32: 4203-0000 | B32: Utilities - RUBS - Trash | C32: 10234.08 | D32: 9600 | E32: 634.08 | F32: 6.6 | G32: 30827.93 | H32: 28800 | I32: 2027.93 | J32: 7.04 | K32: 115200
A33: 4205-0000 | B33: Utilities - RUBS - Pest | C33: 2184.05 | D33: 2225 | E33: -40.95 | F33: -1.84 | G33: 6156.62 | H33: 6625 | I33: -468.38 | J33: -7.07 | K33: 27275
A34: 4206-0000 | B34: Utilities - RUBS - Other | C34: 0 | D34: 0 | E34: 0 | F34: N/A | G34: -99.73 | H34: 0 | I34: -99.73 | J34: N/A | K34: 0
A35: 4210-0000 | B35: Late Fees | C35: 3725 | D35: 4171.88 | E35: -446.88 | F35: -10.71 | G35: 11725 | H35: 12421.88 | I35: -696.88 | J35: -5.61 | K35: 51140.66
A36: 4211-0000 | B36: Interest Income | C36: 768.61 | D36: 0 | E36: 768.61 | F36: N/A | G36: 768.61 | H36: 0 | I36: 768.61 | J36: N/A | K36: 0
A37: 4213-0000 | B37: NSF Fees | C37: 975 | D37: 75 | E37: 900 | F37: 1200 | G37: 2025 | H37: 225 | I37: 1800 | J37: 800 | K37: 900
A38: 4214-0000 | B38: Less: Other Bad Debt | C38: -14206.89 | D38: -4461.89 | E38: -9745 | F38: -218.41 | G38: -18442.28 | H38: -13764.78 | I38: -4677.5 | J38: -33.98 | K38: -55829.49
A39: 4215-0000 | B39: Bad Debt Recovery | C39: 0 | D39: 0 | E39: 0 | F39: N/A | G39: 49.72 | H39: 0 | I39: 49.72 | J39: N/A | K39: 0
A40: 4216-0000 | B40: Miscellaneous | C40: 5 | D40: 0 | E40: 5 | F40: N/A | G40: 5 | H40: 0 | I40: 5 | J40: N/A | K40: 0
A41: 4221-0000 | B41: Move Out Charges | C41: 625 | D41: 500 | E41: 125 | F41: 25 | G41: 865 | H41: 1500 | I41: -635 | J41: -42.33 | K41: 6000
A42: 4223-0000 | B42: Gate and Key Income | C42: 0 | D42: 0 | E42: 0 | F42: N/A | G42: 0 | H42: 25 | I42: -25 | J42: -100 | K42: 75
A43: 4225-0000 | B43: Short Term Premiums | C43: 625.81 | D43: 400 | E43: 225.81 | F43: 56.45 | G43: 2332.83 | H43: 1200 | I43: 1132.83 | J43: 94.4 | K43: 5500
A44: 4226-0000 | B44: Pet Rent | C44: 1475 | D44: 1200 | E44: 275 | F44: 22.92 | G44: 3099.31 | H44: 3560 | I44: -460.69 | J44: -12.94 | K44: 14720
A45: 4227-0000 | B45: Lease Breakage Fee | C45: 10614 | D45: 1427 | E45: 9187 | F45: 643.8 | G45: 24925 | H45: 4281 | I45: 20644 | J45: 482.22 | K45: 17124
A46: 4229-0000 | B46: Application Fees | C46: 4725 | D46: 950 | E46: 3775 | F46: 397.37 | G46: 10050 | H46: 3900 | I46: 6150 | J46: 157.69 | K46: 16000
A47: 4231-0000 | B47: Legal Fees | C47: 433 | D47: 250 | E47: 183 | F47: 73.2 | G47: 1856 | H47: 750 | I47: 1106 | J47: 147.47 | K47: 3000
A48: 4232-0000 | B48: Tenant Charges | C48: 3508 | D48: 0 | E48: 3508 | F48: N/A | G48: 3513 | H48: 0 | I48: 3513 | J48: N/A | K48: 0
...

Sheet Teagen - Input
A2: Income Statement Trailing 12
A3: Teagen
A4: Accrual Basis
A5: Jan 2024 - Dec 2024
A7: Account | B7: Account Name | C7: Jan 2024 | D7: Feb 2024 | E7: Mar 2024 | F7: Apr 2024 | G7: May 2024 | H7: Jun 2024 | I7: Jul 2024 | J7: Aug 2024 | K7: Sep 2024 | L7: Oct 2024 | M7: Nov 2024 | N7: Dec 2024 | O7: Total | Q7: Income Statement: GL Account Type | R7: Income Statement: Property | S7: Income Statement: Property Look-Up Code | T7: Income Statement: Unit Count | U7: Income Statement: Month 1 Change Sign | V7: Income Statement: Month 2 Change Sign | W7: Income Statement: Month 3 Change Sign | X7: Income Statement: Month 4 Change Sign | Y7: Income Statement: Month 5 Change Sign | Z7: Income Statement: Month 6 Change Sign | AA7: Income Statement: Month 7 Change Sign | AB7: Income Statement: Month 8 Change Sign | AC7: Income Statement: Month 9 Change Sign | AD7: Income Statement: Month 10 Change Sign | AE7: Income Statement: Month 11 Change Sign | AF7: Income Statement: Month 12 Change Sign | AG7: Income Statement: Total Change Sign
A8: Income
A9: Rental Income
A10: 5001 | B10: Market Rent | C10: 275633.79 | D10: 275671.73 | E10: 279635.21 | F10: 278835.64 | G10: 275544.36 | H10: 275959.53 | I10: 276405.72 | J10: 274406.38 | K10: 274776.06 | L10: 275160.13 | M10: 267203.42 | N10: 268855.27 | O10: 3298087.2 | Q10: 4 | R10: Teagen | S10: TEA | U10: =IF(5 = Q10, C10 * -1, C10) -> 275633.79 | V10: =IF(5 = Q10, D10 * -1, D10) -> 275671.73 | W10: =IF(5 = Q10, E10 * -1, E10) -> 279635.21 | X10: =IF(5 = Q10, F10 * -1, F10) -> 278835.64 | Y10: =IF(5 = Q10, G10 * -1, G10) -> 275544.36 | Z10: =IF(5 = Q10, H10 * -1, H10) -> 275959.53 | AA10: =IF(5 = Q10, I10 * -1, I10) -> 276405.72 | AB10: =IF(5 = Q10, J10 * -1, J10) -> 274406.38 | AC10: =IF(5 = Q10, K10 * -1, K10) -> 274776.06 | AD10: =IF(5 = Q10, L10 * -1, L10) -> 275160.13 | AE10: =IF(5 = Q10, M10 * -1, M10) -> 267203.42 | AF10: =IF(5 = Q10, N10 * -1, N10) -> 268855.27 | AG10: =IF(5 = Q10, O10 * -1, O10) -> 3298087.2 | AH10: Property Asking Rent
A11: 5002 | B11: Gain/Loss To Lease | C11: -20703.22 | D11: -18666.7 | E11: -21247.26 | F11: -18608.65 | G11: -16892.25 | H11: -17799.09 | I11: -18065.64 | J11: -16178.15 | K11: -14469.73 | L11: -15890.83 | M11: -8271.96 | N11: -9504.2 | O11: -196297.68 | Q11: 4 | R11: Teagen | S11: TEA | U11: =IF(5 = Q11, C11 * -1, C11) -> -20703.22 | V11: =IF(5 = Q11, D11 * -1, D11) -> -18666.7 | W11: =IF(5 = Q11, E11 * -1, E11) -> -21247.26 | X11: =IF(5 = Q11, F11 * -1, F11) -> -18608.65 | Y11: =IF(5 = Q11, G11 * -1, G11) -> -16892.25 | Z11: =IF(5 = Q11, H11 * -1, H11) -> -17799.09 | AA11: =IF(5 = Q11, I11 * -1, I11) -> -18065.64 | AB11: =IF(5 = Q11, J11 * -1, J11) -> -16178.15 | AC11: =IF(5 = Q11, K11 * -1, K11) -> -14469.73 | AD11: =IF(5 = Q11, L11 * -1, L11) -> -15890.83 | AE11: =IF(5 = Q11, M11 * -1, M11) -> -8271.96 | AF11: =IF(5 = Q11, N11 * -1, N11) -> -9504.2 | AG11: =IF(5 = Q11, O11 * -1, O11) -> -196297.68 | AH11: Loss to lease
A12: 5954 | B12: Monthly Yard Revenue | C12: 1574.35 | D12: 1675 | E12: 1617.07 | F12: 1610.69 | G12: 1926.57 | H12: 1904.5 | I12: 2073.58 | J12: 2076.13 | K12: 2181.6 | L12: 2755.32 | M12: 3166.53 | N12: 3339.2 | O12: 25900.54 | Q12: 4 | R12: Teagen | S12: TEA | U12: =IF(5 = Q12, C12 * -1, C12) -> 1574.35 | V12: =IF(5 = Q12, D12 * -1, D12) -> 1675 | W12: =IF(5 = Q12, E12 * -1, E12) -> 1617.07 | X12: =IF(5 = Q12, F12 * -1, F12) -> 1610.69 | Y12: =IF(5 = Q12, G12 * -1, G12) -> 1926.57 | Z12: =IF(5 = Q12, H12 * -1, H12) -> 1904.5 | AA12: =IF(5 = Q12, I12 * -1, I12) -> 2073.58 | AB12: =IF(5 = Q12, J12 * -1, J12) -> 2076.13 | AC12: =IF(5 = Q12, K12 * -1, K12) -> 2181.6 | AD12: =IF(5 = Q12, L12 * -1, L12) -> 2755.32 | AE12: =IF(5 = Q12, M12 * -1, M12) -> 3166.53 | AF12: =IF(5 = Q12, N12 * -1, N12) -> 3339.2 | AG12: =IF(5 = Q12, O12 * -1, O12) -> 25900.54 | AH12: Other
A13: 5006 | B13: Washer/Dryer | C13: -147.13 | D13: 0 | E13: 0 | F13: 0 | G13: 0 | H13: 0 | I13: 0 | J13: 0 | K13: 6.67 | L13: 235.55 | M13: 7818.72 | N13: 7840.82 | O13: 15754.63 | Q13: 4 | R13: Teagen | S13: TEA | U13: =IF(5 = Q13, C13 * -1, C13) -> -147.13 | V13: =IF(5 = Q13, D13 * -1, D13) -> 0 | W13: =IF(5 = Q13, E13 * -1, E13) -> 0 | X13: =IF(5 = Q13, F13 * -1, F13) -> 0 | Y13: =IF(5 = Q13, G13 * -1, G13) -> 0 | Z13: =IF(5 = Q13, H13 * -1, H13) -> 0 | AA13: =IF(5 = Q13, I13 * -1, I13) -> 0 | AB13: =IF(5 = Q13, J13 * -1, J13) -> 0 | AC13: =IF(5 = Q13, K13 * -1, K13) -> 6.67 | AD13: =IF(5 = Q13, L13 * -1, L13) -> 235.55 | AE13: =IF(5 = Q13, M13 * -1, M13) -> 7818.72 | AF13: =IF(5 = Q13, N13 * -1, N13) -> 7840.82 | AG13: =IF(5 = Q13, O13 * -1, O13) -> 15754.63 | AH13: Other
B14: Rental Income | C14: 256357.79 | D14: 258680.03 | E14: 260005.02 | F14: 261837.68 | G14: 260578.68 | H14: 260064.94 | I14: 260413.66 | J14: 260304.36 | K14: 262494.6 | L14: 262260.17 | M14: 269916.71 | N14: 270531.09 | O14: 3143444.7 | Q14: 4 | R14: Teagen | S14: TEA | U14: =IF(5 = Q14, C14 * -1, C14) -> 256357.79 | V14: =IF(5 = Q14, D14 * -1, D14) -> 258680.03 | W14: =IF(5 = Q14, E14 * -1, E14) -> 260005.02 | X14: =IF(5 = Q14, F14 * -1, F14) -> 261837.68 | Y14: =IF(5 = Q14, G14 * -1, G14) -> 260578.68 | Z14: =IF(5 = Q14, H14 * -1, H14) -> 260064.94 | AA14: =IF(5 = Q14, I14 * -1, I14) -> 260413.66 | AB14: =IF(5 = Q14, J14 * -1, J14) -> 260304.36 | AC14: =IF(5 = Q14, K14 * -1, K14) -> 262494.6 | AD14: =IF(5 = Q14, L14 * -1, L14) -> 262260.17 | AE14: =IF(5 = Q14, M14 * -1, M14) -> 269916.71 | AF14: =IF(5 = Q14, N14 * -1, N14) -> 270531.09 | AG14: =IF(5 = Q14, O14 * -1, O14) -> 3143444.7
Q15: 4 | R15: Teagen | S15: TEA | U15: =IF(5 = Q15, C15 * -1, C15) -> 0 | V15: =IF(5 = Q15, D15 * -1, D15) -> 0 | W15: =IF(5 = Q15, E15 * -1, E15) -> 0 | X15: =IF(5 = Q15, F15 * -1, F15) -> 0 | Y15: =IF(5 = Q15, G15 * -1, G15) -> 0 | Z15: =IF(5 = Q15, H15 * -1, H15) -> 0 | AA15: =IF(5 = Q15, I15 * -1, I15) -> 0 | AB15: =IF(5 = Q15, J15 * -1, J15) -> 0 | AC15: =IF(5 = Q15, K15 * -1, K15) -> 0 | AD15: =IF(5 = Q15, L15 * -1, L15) -> 0 | AE15: =IF(5 = Q15, M15 * -1, M15) -> 0 | AF15: =IF(5 = Q15, N15 * -1, N15) -> 0 | AG15: =IF(5 = Q15, O15 * -1, O15) -> 0
A16: Vacancy, Losses & Concessions | Q16: 4 | R16: Teagen | S16: TEA | U16: =IF(5 = Q16, C16 * -1, C16) -> 0 | V16: =IF(5 = Q16, D16 * -1, D16) -> 0 | W16: =IF(5 = Q16, E16 * -1, E16) -> 0 | X16: =IF(5 = Q16, F16 * -1, F16) -> 0 | Y16: =IF(5 = Q16, G16 * -1, G16) -> 0 | Z16: =IF(5 = Q16, H16 * -1, H16) -> 0 | AA16: =IF(5 = Q16, I16 * -1, I16) -> 0 | AB16: =IF(5 = Q16, J16 * -1, J16) -> 0 | AC16: =IF(5 = Q16, K16 * -1, K16) -> 0 | AD16: =IF(5 = Q16, L16 * -1, L16) -> 0 | AE16: =IF(5 = Q16, M16 * -1, M16) -> 0 | AF16: =IF(5 = Q16, N16 * -1, N16) -> 0 | AG16: =IF(5 = Q16, O16 * -1, O16) -> 0
A17: 5102 | B17: Delinquent Rent/Bad Debt | C17: -4074.38 | D17: -9022.6 | E17: -3280.08 | F17: -3161.13 | G17: -11395.38 | H17: -11435.88 | I17: -8348.67 | J17: -15964.4 | K17: -11211.49 | L17: -8522.61 | M17: -11145.94 | N17: -5962.15 | O17: -103524.71 | Q17: 4 | R17: Teagen | S17: TEA | U17: =IF(5 = Q17, C17 * -1, C17) -> -4074.38 | V17: =IF(5 = Q17, D17 * -1, D17) -> -9022.6 | W17: =IF(5 = Q17, E17 * -1, E17) -> -3280.08 | X17: =IF(5 = Q17, F17 * -1, F17) -> -3161.13 | Y17: =IF(5 = Q17, G17 * -1, G17) -> -11395.38 | Z17: =IF(5 = Q17, H17 * -1, H17) -> -11435.88 | AA17: =IF(5 = Q17, I17 * -1, I17) -> -8348.67 | AB17: =IF(5 = Q17, J17 * -1, J17) -> -15964.4 | AC17: =IF(5 = Q17, K17 * -1, K17) -> -11211.49 | AD17: =IF(5 = Q17, L17 * -1, L17) -> -8522.61 | AE17: =IF(5 = Q17, M17 * -1, M17) -> -11145.94 | AF17: =IF(5 = Q17, N17 * -1, N17) -> -5962.15 | AG17: =IF(5 = Q17, O17 * -1, O17) -> -103524.71 | AH17: Delinquency
A18: 5950 | B18: Bad Debt Recovery | C18: 0 | D18: 0 | E18: 0 | F18: 0 | G18: 0 | H18: 801.97 | I18: 5260.42 | J18: 0 | K18: 11656.91 | L18: 4897.48 | M18: 3507.37 | N18: 18318.31 | O18: 44442.46 | Q18: 4 | R18: Teagen | S18: TEA | U18: =IF(5 = Q18, C18 * -1, C18) -> 0 | V18: =IF(5 = Q18, D18 * -1, D18) -> 0 | W18: =IF(5 = Q18, E18 * -1, E18) -> 0 | X18: =IF(5 = Q18, F18 * -1, F18) -> 0 | Y18: =IF(5 = Q18, G18 * -1, G18) -> 0 | Z18: =IF(5 = Q18, H18 * -1, H18) -> 801.97 | AA18: =IF(5 = Q18, I18 * -1, I18) -> 5260.42 | AB18: =IF(5 = Q18, J18 * -1, J18) -> 0 | AC18: =IF(5 = Q18, K18 * -1, K18) -> 11656.91 | AD18: =IF(5 = Q18, L18 * -1, L18) -> 4897.48 | AE18: =IF(5 = Q18, M18 * -1, M18) -> 3507.37 | AF18: =IF(5 = Q18, N18 * -1, N18) -> 18318.31 | AG18: =IF(5 = Q18, O18 * -1, O18) -> 44442.46 | AH18: Other
A19: 5103 | B19: Rental Concessions | C19: -2938 | D19: -1675.88 | E19: -2874.47 | F19: -7759.25 | G19: -3024.95 | H19: -9486.11 | I19: -9028.06 | J19: -11806.63 | K19: -12838.82 | L19: -6397.75 | M19: -10670.5 | N19: -5635.6 | O19: -84136.02 | Q19: 4 | R19: Teagen | S19: TEA | U19: =IF(5 = Q19, C19 * -1, C19) -> -2938 | V19: =IF(5 = Q19, D19 * -1, D19) -> -1675.88 | W19: =IF(5 = Q19, E19 * -1, E19) -> -2874.47 | X19: =IF(5 = Q19, F19 * -1, F19) -> -7759.25 | Y19: =IF(5 = Q19, G19 * -1, G19) -> -3024.95 | Z19: =IF(5 = Q19, H19 * -1, H19) -> -9486.11 | AA19: =IF(5 = Q19, I19 * -1, I19) -> -9028.06 | AB19: =IF(5 = Q19, J19 * -1, J19) -> -11806.63 | AC19: =IF(5 = Q19, K19 * -1, K19) -> -12838.82 | AD19: =IF(5 = Q19, L19 * -1, L19) -> -6397.75 | AE19: =IF(5 = Q19, M19 * -1, M19) -> -10670.5 | AF19: =IF(5 = Q19, N19 * -1, N19) -> -5635.6 | AG19: =IF(5 = Q19, O19 * -1, O19) -> -84136.02 | AH19: Concessions
A20: 5104 | B20: Vacancy Loss | C20: -16258.8 | D20: -15479.74 | E20: -15972.75 | F20: -22854.02 | G20: -21026.49 | H20: -21367.33 | I20: -15568.18 | J20: -18879.51 | K20: -22091.78 | L20: -19608.59 | M20: -14273.23 | N20: -15773.34 | O20: -219153.76 | Q20: 4 | R20: =R19 -> Teagen | S20: =S19 -> TEA | T20: =T19 -> 0 | U20: =SUM(U10:U19) -> 505703.2 | V20: =SUM(V10:V19) -> 506661.58 | W20: =SUM(W10:W19) -> 513855.49 | X20: =SUM(X10:X19) -> 512754.98 | Y20: =SUM(Y10:Y19) -> 506737.03 | Z20: =SUM(Z10:Z19) -> 500009.86 | AA20: =SUM(AA10:AA19) -> 508711.01 | AB20: =SUM(AB10:AB19) -> 492837.69 | ... AG20: =SUM(AG10:AG19) -> 6143671.2 | AH20: Vacancy
A21: 5107 | B21: Employee Rent Discount | C21: -841.5 | D21: -961.74 | E21: -514.2 | F21: -787.5 | G21: -1179.86 | H21: -1179.86 | I21: -1179.86 | J21: -1179.86 | K21: -1179.86 | L21: -1179.86 | M21: -1179.86 | N21: -907.77 | O21: -12271.73 | AH21: Other
A22: 5110 | B22: Preferred Employer Rent Discount | C22: 0 | D22: 0 | E22: 0 | F22: 0 | G22: 0 | H22: 0 | I22: 0 | J22: 0 | K22: 0 | L22: 0 | M22: 0 | N22: -82.89 | O22: -82.89 | AH22: Vacancy
A23: 5109 | B23: Model Vacancy Loss | C23: -1065 | D23: -1065 | E23: -1065 | F23: -1065 | G23: -1065 | H23: -1065 | I23: -1065 | J23: -1065 | K23: -1065 | L23: -839 | M23: -839 | N23: -839 | O23: -12102 | Q23: 4 | R23: Teagen | S23: TEA | U23: =IF(5 = Q23, C23 * -1, C23) -> -1065 | V23: =IF(5 = Q23, D23 * -1, D23) -> -1065 | W23: =IF(5 = Q23, E23 * -1, E23) -> -1065 | X23: =IF(5 = Q23, F23 * -1, F23) -> -1065 | Y23: =IF(5 = Q23, G23 * -1, G23) -> -1065 | Z23: =IF(5 = Q23, H23 * -1, H23) -> -1065 | AA23: =IF(5 = Q23, I23 * -1, I23) -> -1065 | AB23: =IF(5 = Q23, J23 * -1, J23) -> -1065 | AC23: =IF(5 = Q23, K23 * -1, K23) -> -1065 | AD23: =IF(5 = Q23, L23 * -1, L23) -> -839 | AE23: =IF(5 = Q23, M23 * -1, M23) -> -839 | AF23: =IF(5 = Q23, N23 * -1, N23) -> -839 | AG23: =IF(5 = Q23, O23 * -1, O23) -> -12102 | AH23: Non Revenue Units
B24: Vacancy, Losses & Concessions | C24: -25177.68 | D24: -28204.96 | E24: -23706.5 | F24: -35626.9 | G24: -37691.68 | H24: -43732.21 | I24: -29929.35 | J24: -48895.4 | K24: -36730.04 | L24: -31650.33 | M24: -34601.16 | N24: -10882.44 | O24: -386828.65 | Q24: 4 | R24: Teagen | S24: TEA | U24: =IF(5 = Q24, C24 * -1, C24) -> -25177.68 | V24: =IF(5 = Q24, D24 * -1, D24) -> -28204.96 | W24: =IF(5 = Q24, E24 * -1, E24) -> -23706.5 | X24: =IF(5 = Q24, F24 * -1, F24) -> -35626.9 | Y24: =IF(5 = Q24, G24 * -1, G24) -> -37691.68 | Z24: =IF(5 = Q24, H24 * -1, H24) -> -43732.21 | AA24: =IF(5 = Q24, I24 * -1, I24) -> -29929.35 | AB24: =IF(5 = Q24, J24 * -1, J24) -> -48895.4 | AC24: =IF(5 = Q24, K24 * -1, K24) -> -36730.04 | AD24: =IF(5 = Q24, L24 * -1, L24) -> -31650.33 | AE24: =IF(5 = Q24, M24 * -1, M24) -> -34601.16 | AF24: =IF(5 = Q24, N24 * -1, N24) -> -10882.44 | AG24: =IF(5 = Q24, O24 * -1, O24) -> -386828.65
Q25: 4 | R25: Teagen | S25: TEA | U25: =IF(5 = Q25, C25 * -1, C25) -> 0 | V25: =IF(5 = Q25, D25 * -1, D25) -> 0 | W25: =IF(5 = Q25, E25 * -1, E25) -> 0 | X25: =IF(5 = Q25, F25 * -1, F25) -> 0 | Y25: =IF(5 = Q25, G25 * -1, G25) -> 0 | Z25: =IF(5 = Q25, H25 * -1, H25) -> 0 | AA25: =IF(5 = Q25, I25 * -1, I25) -> 0 | AB25: =IF(5 = Q25, J25 * -1, J25) -> 0 | AC25: =IF(5 = Q25, K25 * -1, K25) -> 0 | AD25: =IF(5 = Q25, L25 * -1, L25) -> 0 | AE25: =IF(5 = Q25, M25 * -1, M25) -> 0 | AF25: =IF(5 = Q25, N25 * -1, N25) -> 0 | AG25: =IF(5 = Q25, O25 * -1, O25) -> 0
B26: Net Rental Income | C26: 231180.11 | D26: 230475.07 | E26: 236298.52 | F26: 226210.78 | G26: 222887 | H26: 216332.73 | I26: 230484.31 | J26: 211408.96 | K26: 225764.56 | L26: 230609.84 | M26: 235315.55 | N26: 259648.65 | O26: 2756616.1 | Q26: 4 | R26: Teagen | S26: TEA | U26: =IF(5 = Q26, C26 * -1, C26) -> 231180.11 | V26: =IF(5 = Q26, D26 * -1, D26) -> 230475.07 | W26: =IF(5 = Q26, E26 * -1, E26) -> 236298.52 | X26: =IF(5 = Q26, F26 * -1, F26) -> 226210.78 | Y26: =IF(5 = Q26, G26 * -1, G26) -> 222887 | Z26: =IF(5 = Q26, H26 * -1, H26) -> 216332.73 | AA26: =IF(5 = Q26, I26 * -1, I26) -> 230484.31 | AB26: =IF(5 = Q26, J26 * -1, J26) -> 211408.96 | AC26: =IF(5 = Q26, K26 * -1, K26) -> 225764.56 | AD26: =IF(5 = Q26, L26 * -1, L26) -> 230609.84 | AE26: =IF(5 = Q26, M26 * -1, M26) -> 235315.55 | AF26: =IF(5 = Q26, N26 * -1, N26) -> 259648.65 | AG26: =IF(5 = Q26, O26 * -1, O26) -> 2756616.1
Q27: 4 | R27: Teagen | S27: TEA | U27: =IF(5 = Q27, C27 * -1, C27) -> 0 | V27: =IF(5 = Q27, D27 * -1, D27) -> 0 | W27: =IF(5 = Q27, E27 * -1, E27) -> 0 | X27: =IF(5 = Q27, F27 * -1, F27) -> 0 | Y27: =IF(5 = Q27, G27 * -1, G27) -> 0 | Z27: =IF(5 = Q27, H27 * -1, H27) -> 0 | AA27: =IF(5 = Q27, I27 * -1, I27) -> 0 | AB27: =IF(5 = Q27, J27 * -1, J27) -> 0 | AC27: =IF(5 = Q27, K27 * -1, K27) -> 0 | AD27: =IF(5 = Q27, L27 * -1, L27) -> 0 | AE27: =IF(5 = Q27, M27 * -1, M27) -> 0 | AF27: =IF(5 = Q27, N27 * -1, N27) -> 0 | AG27: =IF(5 = Q27, O27 * -1, O27) -> 0
A28: Other Income | Q28: 4 | R28: Teagen | S28: TEA | U28: =IF(5 = Q28, C28 * -1, C28) -> 0 | V28: =IF(5 = Q28, D28 * -1, D28) -> 0 | W28: =IF(5 = Q28, E28 * -1, E28) -> 0 | X28: =IF(5 = Q28, F28 * -1, F28) -> 0 | Y28: =IF(5 = Q28, G28 * -1, G28) -> 0 | Z28: =IF(5 = Q28, H28 * -1, H28) -> 0 | AA28: =IF(5 = Q28, I28 * -1, I28) -> 0 | AB28: =IF(5 = Q28, J28 * -1, J28) -> 0 | AC28: =IF(5 = Q28, K28 * -1, K28) -> 0 | AD28: =IF(5 = Q28, L28 * -1, L28) -> 0 | AE28: =IF(5 = Q28, M28 * -1, M28) -> 0 | AF28: =IF(5 = Q28, N28 * -1, N28) -> 0 | AG28: =IF(5 = Q28, O28 * -1, O28) -> 0
A29: 5007 | B29: Other Income - Monthly Pet Rent | C29: 1435.58 | D29: 1672.67 | E29: 1583.91 | F29: 1475.17 | G29: 1491.55 | H29: 1374.68 | I29: 1532.01 | J29: 1448.71 | K29: 1413 | L29: 1361.6 | M29: 1338 | N29: 1351.16 | O29: 17478.04 | Q29: 4 | R29: Teagen | S29: TEA | U29: =IF(5 = Q29, C29 * -1, C29) -> 1435.58 | V29: =IF(5 = Q29, D29 * -1, D29) -> 1672.67 | W29: =IF(5 = Q29, E29 * -1, E29) -> 1583.91 | X29: =IF(5 = Q29, F29 * -1, F29) -> 1475.17 | Y29: =IF(5 = Q29, G29 * -1, G29) -> 1491.55 | Z29: =IF(5 = Q29, H29 * -1, H29) -> 1374.68 | AA29: =IF(5 = Q29, I29 * -1, I29) -> 1532.01 | AB29: =IF(5 = Q29, J29 * -1, J29) -> 1448.71 | AC29: =IF(5 = Q29, K29 * -1, K29) -> 1413 | AD29: =IF(5 = Q29, L29 * -1, L29) -> 1361.6 | AE29: =IF(5 = Q29, M29 * -1, M29) -> 1338 | AF29: =IF(5 = Q29, N29 * -1, N29) -> 1351.16 | AG29: =IF(5 = Q29, O29 * -1, O29) -> 17478.04 | AH29: Other
A30: 5013 | B30: Other Income - Washer/Dryer Rental | C30: 5834.5 | D30: 6419.63 | E30: 6549.65 | F30: 6153.55 | G30: 6702.92 | H30: 6884.73 | I30: 7125.52 | J30: 7459.37 | K30: 7014.61 | L30: 7267.37 | M30: 0 | N30: 0 | O30: 67411.85 | Q30: 4 | R30: Teagen | S30: TEA | U30: =IF(5 = Q30, C30 * -1, C30) -> 5834.5 | V30: =IF(5 = Q30, D30 * -1, D30) -> 6419.63 | W30: =IF(5 = Q30, E30 * -1, E30) -> 6549.65 | X30: =IF(5 = Q30, F30 * -1, F30) -> 6153.55 | Y30: =IF(5 = Q30, G30 * -1, G30) -> 6702.92 | Z30: =IF(5 = Q30, H30 * -1, H30) -> 6884.73 | AA30: =IF(5 = Q30, I30 * -1, I30) -> 7125.52 | AB30: =IF(5 = Q30, J30 * -1, J30) -> 7459.37 | AC30: =IF(5 = Q30, K30 * -1, K30) -> 7014.61 | AD30: =IF(5 = Q30, L30 * -1, L30) -> 7267.37 | AE30: =IF(5 = Q30, M30 * -1, M30) -> 0 | AF30: =IF(5 = Q30, N30 * -1, N30) -> 0 | AG30: =IF(5 = Q30, O30 * -1, O30) -> 67411.85 | AH30: Other
A31: 5202 | B31: Other Income - Cable TV Income | C31: 0 | D31: 1778.02 | E31: 0 | F31: 0 | G31: 1815.18 | H31: 0 | I31: 0 | J31: 1619.51 | K31: 0 | L31: 0 | M31: 1709.16 | N31: 0 | O31: 6921.87 | Q31: 4 | R31: Teagen | S31: TEA | U31: =IF(5 = Q31, C31 * -1, C31) -> 0 | V31: =IF(5 = Q31, D31 * -1, D31) -> 1778.02 | W31: =IF(5 = Q31, E31 * -1, E31) -> 0 | X31: =IF(5 = Q31, F31 * -1, F31) -> 0 | Y31: =IF(5 = Q31, G31 * -1, G31) -> 1815.18 | Z31: =IF(5 = Q31, H31 * -1, H31) -> 0 | AA31: =IF(5 = Q31, I31 * -1, I31) -> 0 | AB31: =IF(5 = Q31, J31 * -1, J31) -> 1619.51 | AC31: =IF(5 = Q31, K31 * -1, K31) -> 0 | AD31: =IF(5 = Q31, L31 * -1, L31) -> 0 | AE31: =IF(5 = Q31, M31 * -1, M31) -> 1709.16 | AF31: =IF(5 = Q31, N31 * -1, N31) -> 0 | AG31: =IF(5 = Q31, O31 * -1, O31) -> 6921.87 | AH31: Other
A32: 5204 | B32: Other Income - Loss Damage Waiver | C32: 4271.18 | D32: 4264.78 | E32: 4273.45 | F32: 4210.35 | G32: 4258.97 | H32: 4290.01 | I32: 4428.15 | J32: 4392.24 | K32: 4380.39 | L32: 4484.2 | M32: 4591.86 | N32: 4618.45 | O32: 52464.03 | Q32: 4 | R32: Teagen | S32: TEA | U32: =IF(5 = Q32, C32 * -1, C32) -> 4271.18 | V32: =IF(5 = Q32, D32 * -1, D32) -> 4264.78 | W32: =IF(5 = Q32, E32 * -1, E32) -> 4273.45 | X32: =IF(5 = Q32, F32 * -1, F32) -> 4210.35 | Y32: =IF(5 = Q32, G32 * -1, G32) -> 4258.97 | Z32: =IF(5 = Q32, H32 * -1, H32) -> 4290.01 | AA32: =IF(5 = Q32, I32 * -1, I32) -> 4428.15 | AB32: =IF(5 = Q32, J32 * -1, J32) -> 4392.24 | AC32: =IF(5 = Q32, K32 * -1, K32) -> 4380.39 | AD32: =IF(5 = Q32, L32 * -1, L32) -> 4484.2 | AE32: =IF(5 = Q32, M32 * -1, M32) -> 4591.86 | AF32: =IF(5 = Q32, N32 * -1, N32) -> 4618.45 | AG32: =IF(5 = Q32, O32 * -1, O32) -> 52464.03 | AH32: Other
A33: 5205 | B33: Other Income - Conditional Fees | C33: 0 | D33: 0 | E33: 0 | F33: 0 | G33: 0 | H33: 0 | I33: 0 | J33: 0 | K33: 2000 | L33: 3000 | M33: 2000 | N33: 0 | O33: 7000 | Q33: 4 | R33: Teagen | S33: TEA | U33: =IF(5 = Q33, C33 * -1, C33) -> 0 | V33: =IF(5 = Q33, D33 * -1, D33) -> 0 | W33: =IF(5 = Q33, E33 * -1, E33) -> 0 | X33: =IF(5 = Q33, F33 * -1, F33) -> 0 | Y33: =IF(5 = Q33, G33 * -1, G33) -> 0 | Z33: =IF(5 = Q33, H33 * -1, H33) -> 0 | AA33: =IF(5 = Q33, I33 * -1, I33) -> 0 | AB33: =IF(5 = Q33, J33 * -1, J33) -> 0 | AC33: =IF(5 = Q33, K33 * -1, K33) -> 2000 | AD33: =IF(5 = Q33, L33 * -1, L33) -> 3000 | AE33: =IF(5 = Q33, M33 * -1, M33) -> 2000 | AF33: =IF(5 = Q33, N33 * -1, N33) -> 0 | AG33: =IF(5 = Q33, O33 * -1, O33) -> 7000 | AH33: Other
A34: 5211 | B34: Other Income - Water/Sewer Reimbursements | C34: 14756.57 | D34: 20075.59 | E34: 17871.27 | F34: 14651.06 | G34: 22486.9 | H34: 19185.04 | I34: 20364.79 | J34: 19386.27 | K34: 13688.34 | L34: 18777.85 | M34: 15811.63 | N34: 16539.64 | O34: 213594.95 | Q34: 4 | R34: Teagen | S34: TEA | U34: =IF(5 = Q34, C34 * -1, C34) -> 14756.57 | V34: =IF(5 = Q34, D34 * -1, D34) -> 20075.59 | W34: =IF(5 = Q34, E34 * -1, E34) -> 17871.27 | X34: =IF(5 = Q34, F34 * -1, F34) -> 14651.06 | Y34: =IF(5 = Q34, G34 * -1, G34) -> 22486.9 | Z34: =IF(5 = Q34, H34 * -1, H34) -> 19185.04 | AA34: =IF(5 = Q34, I34 * -1, I34) -> 20364.79 | AB34: =IF(5 = Q34, J34 * -1, J34) -> 19386.27 | AC34: =IF(5 = Q34, K34 * -1, K34) -> 13688.34 | AD34: =IF(5 = Q34, L34 * -1, L34) -> 18777.85 | AE34: =IF(5 = Q34, M34 * -1, M34) -> 15811.63 | AF34: =IF(5 = Q34, N34 * -1, N34) -> 16539.64 | AG34: =IF(5 = Q34, O34 * -1, O34) -> 213594.95 | AH34: Other
A35: 5212 | B35: Other Income - Trash Reimbursements | C35: 10823.08 | D35: 10749.88 | E35: 10756.78 | F35: 10593.18 | G35: 10633.19 | H35: 10610.51 | I35: 10877.2 | J35: 10688.89 | K35: 10659.37 | L35: 10815.55 | M35: 10962.75 | N35: 11066.79 | O35: 129237.17 | Q35: 4 | R35: Teagen | S35: TEA | U35: =IF(5 = Q35, C35 * -1, C35) -> 10823.08 | V35: =IF(5 = Q35, D35 * -1, D35) -> 10749.88 | W35: =IF(5 = Q35, E35 * -1, E35) -> 10756.78 | X35: =IF(5 = Q35, F35 * -1, F35) -> 10593.18 | Y35: =IF(5 = Q35, G35 * -1, G35) -> 10633.19 | Z35: =IF(5 = Q35, H35 * -1, H35) -> 10610.51 | AA35: =IF(5 = Q35, I35 * -1, I35) -> 10877.2 | AB35: =IF(5 = Q35, J35 * -1, J35) -> 10688.89 | AC35: =IF(5 = Q35, K35 * -1, K35) -> 10659.37 | AD35: =IF(5 = Q35, L35 * -1, L35) -> 10815.55 | AE35: =IF(5 = Q35, M35 * -1, M35) -> 10962.75 | AF35: =IF(5 = Q35, N35 * -1, N35) -> 11066.79 | AG35: =IF(5 = Q35, O35 * -1, O35) -> 129237.17 | AH35: Other
A36: 5220 | B36: Other Income - Pest Control Reimbursement | C36: 2276.63 | D36: 2269.5 | E36: 2265.95 | F36: 2221.31 | G36: 2241.37 | H36: 2236.77 | I36: 2291.61 | J36: 2258.58 | K36: 2235.97 | L36: 2203.93 | M36: 2116.57 | N36: 1986.52 | O36: 26604.71 | Q36: 4 | R36: =R35 -> Teagen | S36: =S35 -> TEA | T36: =T35 -> 0 | U36: =SUM(U23:U35) -> 242058.34 | V36: =SUM(V23:V35) -> 246165.68 | W36: =SUM(W23:W35) -> 252562.08 | X36: =SUM(X23:X35) -> 226602.19 | Y36: =SUM(Y23:Y35) -> 231519.03 | Z36: =SUM(Z23:Z35) -> 213880.49 | AA36: =SUM(AA23:AA35) -> 243817.63 | AB36: =SUM(AB23:AB35) -> 206443.55 | ... AG36: =SUM(AG23:AG35) -> 2851793.3 | AH36: Other
A37: 5804 | B37: Other Income - Amenity Fee | C37: 2890.72 | D37: 2887.61 | E37: 2881.98 | F37: 2867.49 | G37: 2962.51 | H37: 3020.08 | I37: 3159.36 | J37: 3170.01 | K37: 3172.01 | L37: 3144.56 | M37: 3042.66 | N37: 2839.16 | O37: 36038.15 | AH37: Other
A38: 5805 | B38: Other Income - Late Charges | C38: 4050 | D38: 3950 | E38: 3200 | F38: 4200 | G38: 3250 | H38: 3650 | I38: 4600 | J38: 3700 | K38: 4700 | L38: 3100 | M38: 2650 | N38: 4150 | O38: 45200 | Q38: 4 | R38: =R35 -> Teagen | S38: =S35 -> TEA | T38: =T35 -> 0 | U38: =SUM(U10:U19)+SUM(U23:U35) -> 747761.54 | V38: =SUM(V10:V19)+SUM(V23:V35) -> 752827.26 | W38: =SUM(W10:W19)+SUM(W23:W35) -> 766417.57 | X38: =SUM(X10:X19)+SUM(X23:X35) -> 739357.17 | Y38: =SUM(Y10:Y19)+SUM(Y23:Y35) -> 738256.06 | Z38: =SUM(Z10:Z19)+SUM(Z23:Z35) -> 713890.35 | AA38: =SUM(AA10:AA19)+SUM(AA23:AA35) -> 752528.64 | AB38: =SUM(AB10:AB19)+SUM(AB23:AB35) -> 699281.24 | ... AG38: =SUM(AG10:AG19)+SUM(AG23:AG35) -> 8995464.5 | AH38: Other
A39: 5860 | B39: Other Income - Parcel Services Income | C39: 2565.41 | D39: 2562.71 | E39: 2573.96 | F39: 2544.38 | G39: 2601.93 | H39: 2628.41 | I39: 2725.48 | J39: 2714.26 | K39: 2711.96 | L39: 2695.5 | M39: 2603.6 | N39: 2452.29 | O39: 31379.89 | AH39: Other
A40: 5861 | B40: Other Income - Lease Lock | C40: 4746.1 | D40: 5212.33 | E40: 5675.69 | F40: 6153.54 | G40: 6680.23 | H40: 7024.97 | I40: 7530.88 | J40: 7487.81 | K40: 7565.76 | L40: 7894.82 | M40: 8093.41 | N40: 8169.25 | O40: 82234.79 | AH40: Other
A41: 5890 | B41: Other Income - Miscellaneous Income | C41: 112.12 | D41: 50 | E41: 275 | F41: 860 | G41: 415 | H41: 536.85 | I41: 358.15 | J41: 465.6 | K41: 768.75 | L41: 1059 | M41: 1604.1 | N41: 1510.05 | O41: 8014.62 | Q41: 4 | R41: Teagen | S41: TEA | U41: =IF(5 = Q41, C41 * -1, C41) -> 112.12 | V41: =IF(5 = Q41, D41 * -1, D41) -> 50 | W41: =IF(5 = Q41, E41 * -1, E41) -> 275 | X41: =IF(5 = Q41, F41 * -1, F41) -> 860 | Y41: =IF(5 = Q41, G41 * -1, G41) -> 415 | Z41: =IF(5 = Q41, H41 * -1, H41) -> 536.85 | AA41: =IF(5 = Q41, I41 * -1, I41) -> 358.15 | AB41: =IF(5 = Q41, J41 * -1, J41) -> 465.6 | AC41: =IF(5 = Q41, K41 * -1, K41) -> 768.75 | AD41: =IF(5 = Q41, L41 * -1, L41) -> 1059 | AE41: =IF(5 = Q41, M41 * -1, M41) -> 1604.1 | AF41: =IF(5 = Q41, N41 * -1, N41) -> 1510.05 | AG41: =IF(5 = Q41, O41 * -1, O41) -> 8014.62 | AH41: Other
A42: 5891 | B42: Other Income - NSF Charges | C42: 917.31 | D42: 582.69 | E42: 450 | F42: 375 | G42: 75 | H42: 150 | I42: 225 | J42: 150 | K42: 225 | L42: 225 | M42: 75 | N42: 150 | O42: 3600 | Q42: 4 | R42: Teagen | S42: TEA | U42: =IF(5 = Q42, C42 * -1, C42) -> 917.31 | V42: =IF(5 = Q42, D42 * -1, D42) -> 582.69 | W42: =IF(5 = Q42, E42 * -1, E42) -> 450 | X42: =IF(5 = Q42, F42 * -1, F42) -> 375 | Y42: =IF(5 = Q42, G42 * -1, G42) -> 75 | Z42: =IF(5 = Q42, H42 * -1, H42) -> 150 | AA42: =IF(5 = Q42, I42 * -1, I42) -> 225 | AB42: =IF(5 = Q42, J42 * -1, J42) -> 150 | AC42: =IF(5 = Q42, K42 * -1, K42) -> 225 | AD42: =IF(5 = Q42, L42 * -1, L42) -> 225 | AE42: =IF(5 = Q42, M42 * -1, M42) -> 75 | AF42: =IF(5 = Q42, N42 * -1, N42) -> 150 | AG42: =IF(5 = Q42, O42 * -1, O42) -> 3600 | AH42: Other
...

Sheet Teagen - Variance
A2: P/L Report
A3: Teagen
A4: Jun 2024
A5: Accrual Basis
C7: Jun 2024 | H7: YTD ( Jan 2024 - Jun 2024 )
A8: Account | B8: Account Name | C8: Actual | D8: Budget | E8: $ Variance | F8: % Variance | G8: Variance Notes | H8: Actual | I8: Budget | J8: $ Variance | K8: % Variance | M8: Income Statement Budget Vs Actual: Per Sq.Ft. | N8: Income Statement Budget Vs Actual: Per Unit | O8: Income Statement Budget Vs Actual: May 2023 | P8: Income Statement Budget Vs Actual: Actual | Q8: Income Statement Budget Vs Actual: Budget | R8: Income Statement Budget Vs Actual: Per Sq.Ft. | S8: Income Statement Budget Vs Actual: YTD ( 2023 ) | T8: Income Statement Budget Vs Actual: % of Income | U8: Income Statement Budget Vs Actual: % of Income | V8: Income Statement Budget Vs Actual: Prior Year End | W8: Income Statement Budget Vs Actual: Annual Budget | X8: Income Statement Budget Vs Actual: Per Sq.Ft. (Annualized) | Y8: Income Statement Budget Vs Actual: GL Account Type Id | Z8: Income Statement Budget Vs Actual: % of Income | AA8: Income Statement Budget Vs Actual: % of Income | AB8: Income Statement Budget Vs Actual: % of Income | AC8: Income Statement Budget Vs Actual: % of Income | AD8: Income Statement Budget Vs Actual: Prior Mtd Actual Changed Sign | AE8: Income Statement Budget Vs Actual: Mtd Actual Changed Sign | AF8: Income Statement Budget Vs Actual: Mtd Budget Changed Sign | AG8: Income Statement Budget Vs Actual: Mtd Variance Temp | AH8: Income Statement Budget Vs Actual: Prior Ytd Actual Changed Sign | AI8: Income Statement Budget Vs Actual: Prior Year Actual Changed Sign | AJ8: Income Statement Budget Vs Actual: Ytd Actual Changed Sign | AK8: Income Statement Budget Vs Actual: Ytd Budget Changed Sign | AL8: Income Statement Budget Vs Actual: Annual Budget Changed Sign | AM8: Income Statement Budget Vs Actual: Ytd Variance Temp | AN8: Income Statement Budget Vs Actual: Income Expense Converter | AO8: Income Statement Budget Vs Actual: Variance Converter
A9: Income
A10: Rental Income
A11: 5001 | B11: Market Rent | C11: 275959.53 | D11: 283033.12 | E11: -7073.59 | F11: -0.024992093 | G11: This reflects the difference between market rent and effective rent. The number changes based on rent offers and occupancy goals. Pricing is reviewed weekly. | H11: 1661280.3 | I11: 1672131.4 | J11: -10851.18 | K11: -0.00648943 | O11: 265528.07 | S11: 1350334.2 | T11: 1492779.8 | U11: 1453480.7 | V11: 3218646.9 | W11: 3406969.3 | Y11: 4 | Z11: 301371.65 | AA11: 297526.14 | AD11: 265528.07 | AE11: 275544.36 | AF11: 281293.01 | AG11: -5748.65 | AH11: 1350334.2 | AI11: 3218646.9 | AJ11: 1385320.7 | AK11: 1389098.3 | AL11: 3406969.3 | AM11: -3777.59 | AN11: 1 | AO11: 1
A12: 5002 | B12: Gain/Loss To Lease | C12: -17799.09 | D12: -15912.15 | E12: -1886.94 | F12: -0.11858485 | G12: This reflects the difference between market rent and actual rent per unit. | H12: -113917.17 | I12: -101049.45 | J12: -12867.72 | K12: -0.12734082 | O12: -14229.48 | S12: -111704.61 | T12: 1492779.8 | U12: 1453480.7 | V12: -193326.84 | W12: -188549.27 | Y12: 4 | Z12: 301371.65 | AA12: 297526.14 | AD12: -14229.48 | AE12: -16892.25 | AF12: -16286.54 | AG12: -605.71 | AH12: -111704.61 | AI12: -193326.84 | AJ12: -96118.08 | AK12: -85137.3 | AL12: -188549.27 | AM12: -10980.78 | AN12: 1 | AO12: 1
A13: 5954 | B13: Monthly Yard Revenue | C13: 1904.5 | D13: 0 | E13: 1904.5 | F13: 1 | G13: This reflects fifteen residents paying $125 for a pet yard, one paying $65 and five paying $60 per month. | H13: 10308.18 | I13: 0 | J13: 10308.18 | K13: 1 | O13: 556.93 | S13: 1726.34 | T13: 1492779.8 | U13: 1453480.7 | V13: 9166.08 | W13: 0 | Y13: 4 | Z13: 301371.65 | AA13: 297526.14 | AD13: 556.93 | AE13: 1926.57 | AF13: 0 | AG13: 1926.57 | AH13: 1726.34 | AI13: 9166.08 | AJ13: 8403.68 | AK13: 0 | AL13: 0 | AM13: 8403.68 | AN13: 1 | AO13: 1
A14: 5006 | B14: Washer/Dryer | C14: 0 | D14: 0 | E14: 0 | F14: 0 | H14: -147.13 | I14: 0 | J14: -147.13 | K14: -1 | O14: 0 | S14: 0 | T14: 1492779.8 | U14: 1453480.7 | V14: 147.13 | W14: 0 | Y14: 4 | Z14: 301371.65 | AA14: 297526.14 | AD14: 0 | AE14: 0 | AF14: 0 | AG14: 0 | AH14: 0 | AI14: 147.13 | AJ14: -147.13 | AK14: 0 | AL14: 0 | AM14: -147.13 | AN14: 1 | AO14: 1
B15: Rental Income | C15: 260064.94 | D15: 267120.97 | E15: -7056.03 | F15: -0.026415111 | H15: 1557524.1 | I15: 1571082 | J15: -13557.85 | K15: -0.008629626 | O15: 251855.52 | S15: 1240356 | V15: 3034633.3 | W15: 3218420 | Y15: 4 | AD15: 251855.52 | AE15: 260578.68 | AF15: 265006.47 | AG15: -4427.79 | AH15: 1240356 | AI15: 3034633.3 | AJ15: 1297459.2 | AK15: 1303961 | AL15: 3218420 | AM15: -6501.82
A16: Vacancy, Losses & Concessions
A17: 5102 | B17: Delinquent Rent/Bad Debt | C17: -11435.88 | D17: -5500 | E17: -5935.88 | F17: -1.0792509 | H17: -42369.45 | I17: -37500 | J17: -4869.45 | K17: -0.129852 | O17: -2677.99 | S17: -23218.86 | T17: 1492779.8 | U17: 1453480.7 | V17: -75952.42 | W17: -66000 | Y17: 4 | Z17: 301371.65 | AA17: 297526.14 | AD17: -2677.99 | AE17: -11395.38 | AF17: -5500 | AG17: -5895.38 | AH17: -23218.86 | AI17: -75952.42 | AJ17: -30933.57 | AK17: -32000 | AL17: -66000 | AM17: 1066.43 | AN17: 1 | AO17: 1
A18: 5950 | B18: Bad Debt Recovery | C18: 801.97 | D18: 0 | E18: 801.97 | F18: 1 | H18: 801.97 | I18: 0 | J18: 801.97 | K18: 1 | O18: 0 | S18: -7849.43 | T18: 1492779.8 | U18: 1453480.7 | V18: -58789.51 | W18: -12000 | Y18: 4 | Z18: 301371.65 | AA18: 297526.14 | AD18: 0 | AE18: -3024.95 | AF18: -1000 | AG18: -2024.95 | AH18: -7849.43 | AI18: -58789.51 | AJ18: -18272.55 | AK18: -5000 | AL18: -12000 | AM18: -13272.55 | AN18: 1 | AO18: 1
A19: 5103 | B19: Rental Concessions | C19: -9486.11 | D19: -1000 | E19: -8486.11 | F19: -8.48611 | G19: This reflects seven veteran/military discounts, eighteen $500.00 Move-In Specials and one $250.00 Move-In Special. | H19: -27758.66 | I19: -6000 | J19: -21758.66 | K19: -3.6264433 | O19: -19336.73 | S19: -119429.33 | T19: 1492779.8 | U19: 1453480.7 | V19: -281245.32 | W19: -166253.48 | Y19: 4 | Z19: 301371.65 | AA19: 297526.14 | AD19: -19336.73 | AE19: -21026.49 | AF19: -13802.15 | AG19: -7224.34 | AH19: -119429.33 | AI19: -281245.32 | AJ19: -91591.8 | AK19: -68667.42 | AL19: -166253.48 | AM19: -22924.38 | AN19: 1 | AO19: 1
A20: 5104 | B20: Vacancy Loss | C20: -21367.33 | D20: -13836.66 | E20: -7530.67 | F20: -0.5442549 | G20: This reflects the vacancy loss for the month vs. budgeted. The average occupancy for the month was 90.25% vs. 95% | H20: -112959.13 | I20: -82504.08 | J20: -30455.05 | K20: -0.36913387 | O20: -1168.45 | S20: -5304.64 | T20: 1492779.8 | U20: 1453480.7 | V20: -11113.2 | W20: -21000 | Y20: 4 | Z20: 301371.65 | AA20: 297526.14 | AD20: -1168.45 | AE20: -1179.86 | AF20: -1750 | AG20: 570.14 | AH20: -5304.64 | AI20: -11113.2 | AJ20: -4284.8 | AK20: -8750 | AL20: -21000 | AM20: 4465.2 | AN20: 1 | AO20: 1
A21: 5107 | B21: Employee Rent Discount | C21: -1179.86 | D21: -1750 | E21: 570.14 | F21: 0.32579429 | G21: This reflects four employees who live on site and receiving the monthly employee discount. | H21: -5464.66 | I21: -10500 | J21: 5035.34 | K21: 0.47955619 | O21: -972 | S21: -4894 | T21: 1492779.8 | U21: 1453480.7 | V21: -11740 | W21: -12355.36 | Y21: 4 | Z21: 301371.65 | AA21: 297526.14 | AD21: -972 | AE21: -1065 | AF21: -1025.73 | AG21: -39.27 | AH21: -4894 | AI21: -11740 | AJ21: -5325 | AK21: -5103.12 | AL21: -12355.36 | AM21: -221.88 | AN21: 1 | AO21: 1
A22: 5109 | B22: Model Vacancy Loss | C22: -1065 | D22: -1028.29 | E22: -36.71 | F22: -0.035700046 | G22: This reflects one one bedroom one bathroom model apartment home. | H22: -6390 | I22: -6131.41 | J22: -258.59 | K22: -0.042174638 | O22: -24155.17 | S22: -160696.26 | V22: -438840.45 | W22: -277608.84 | Y22: 4 | AD22: -24155.17 | AE22: -37691.68 | AF22: -23077.88 | AG22: -14613.8 | AH22: -160696.26 | AI22: -438840.45 | AJ22: -150407.72 | AK22: -119520.54 | AL22: -277608.84 | AM22: -30887.18
B23: Vacancy, Losses & Concessions | C23: -43732.21 | D23: -23114.95 | E23: -20617.26 | F23: -0.89194482 | H23: -194139.93 | I23: -142635.49 | J23: -51504.44 | K23: -0.36109134 | O23: 227700.35 | S23: 1079659.7 | V23: 2595792.8 | W23: 2940811.2 | Y23: 4 | AD23: 227700.35 | AE23: 222887 | AF23: 241928.59 | AG23: -19041.59 | AH23: 1079659.7 | AI23: 2595792.8 | AJ23: 1147051.5 | AK23: 1184440.5 | AL23: 2940811.2 | AM23: -37389
B24: Net Rental Income | C24: 216332.73 | D24: 244006.02 | E24: -27673.29 | F24: -0.11341232 | H24: 1363384.2 | I24: 1428446.5 | J24: -65062.29 | K24: -0.045547586
A25: Other Income | O25: 908.88 | S25: 4391.07 | T25: 1492779.8 | U25: 1453480.7 | V25: 11227.82 | W25: 10950 | Y25: 4 | Z25: 301371.65 | AA25: 297526.14 | AD25: 908.88 | AE25: 1491.55 | AF25: 875 | AG25: 616.55 | AH25: 4391.07 | AI25: 11227.82 | AJ25: 7658.88 | AK25: 4125 | AL25: 10950 | AM25: 3533.88 | AN25: 1 | AO25: 1
A26: 5007 | B26: Other Income - Monthly Pet Rent | C26: 1374.68 | D26: 900 | E26: 474.68 | F26: 0.52742222 | G26: This reflects income collected for pet rent for the month. The property is charging $30 per pet for pet rent. | H26: 9033.56 | I26: 5025 | J26: 4008.56 | K26: 0.79772338 | O26: 3379.69 | S26: 13857.14 | T26: 1492779.8 | U26: 1453480.7 | V26: 44299.16 | W26: 48480 | Y26: 4 | Z26: 301371.65 | AA26: 297526.14 | AD26: 3379.69 | AE26: 6702.92 | AF26: 3890 | AG26: 2812.92 | AH26: 13857.14 | AI26: 44299.16 | AJ26: 31660.25 | AK26: 18450 | AL26: 48480 | AM26: 13210.25 | AN26: 1 | AO26: 1
A27: 5013 | B27: Other Income - Washer/Dryer Rental | C27: 6884.73 | D27: 3990 | E27: 2894.73 | F27: 0.72549624 | G27: This reflects income collected for washer/dryer connection rent for the month. The property is charging $20.00 per unit for connections and $50 per rental set. As of June 1, 2024 rental sets are priced at $75.00. | H27: 38544.98 | I27: 22440 | J27: 16104.98 | K27: 0.71769073 | O27: 1601.15 | S27: 3221.86 | T27: 1492779.8 | U27: 1453480.7 | V27: 6588.96 | W27: 6600 | Y27: 4 | Z27: 301371.65 | AA27: 297526.14 | AD27: 1601.15 | AE27: 1815.18 | AF27: 0 | AG27: 1815.18 | AH27: 3221.86 | AI27: 6588.96 | AJ27: 3593.2 | AK27: 1650 | AL27: 6600 | AM27: 1943.2 | AN27: 1 | AO27: 1
A28: 5202 | B28: Other Income - Cable TV Income | C28: 0 | D28: 1650 | E28: -1650 | F28: -1 | H28: 3593.2 | I28: 3300 | J28: 293.2 | K28: 0.088848485 | O28: 2851.87 | S28: 11183.21 | T28: 1492779.8 | U28: 1453480.7 | V28: 37343.3 | W28: 53352 | Y28: 4 | Z28: 301371.65 | AA28: 297526.14 | AD28: 2851.87 | AE28: 4258.97 | AF28: 4446 | AG28: -187.03 | AH28: 11183.21 | AI28: 37343.3 | AJ28: 21278.73 | AK28: 22230 | AL28: 53352 | AM28: -951.27 | AN28: 1 | AO28: 1
A29: 5204 | B29: Other Income - Loss Damage Waiver | C29: 4290.01 | D29: 4446 | E29: -155.99 | F29: -0.03508547 | G29: This reflects income collected for RLL for insurance income for the month. The property is charging $16 per unit with new move-ins and renewing residents. | H29: 25568.74 | I29: 26676 | J29: -1107.26 | K29: -0.041507722 | O29: 16181.08 | S29: 68246.35 | T29: 1492779.8 | U29: 1453480.7 | V29: 172145.26 | W29: 164825 | Y29: 4 | Z29: 301371.65 | AA29: 297526.14 | AD29: 16181.08 | AE29: 22486.9 | AF29: 13675 | AG29: 8811.9 | AH29: 68246.35 | AI29: 172145.26 | AJ29: 89841.39 | AK29: 67850 | AL29: 164825 | AM29: 21991.39 | AN29: 1 | AO29: 1
A30: 5211 | B30: Other Income - Water/Sewer Reimbursements | C30: 19185.04 | D30: 14000 | E30: 5185.04 | F30: 0.37036 | G30: This reflects reimbursements billed for the month. Residents are currently billed through Entrata Utilities at the 95% bill-back rate. | H30: 109026.43 | I30: 81850 | J30: 27176.43 | K30: 0.33202724 | O30: 7195.99 | S30: 28019.59 | T30: 1492779.8 | U30: 1453480.7 | V30: 97861.98 | W30: 124488 | Y30: 4 | Z30: 301371.65 | AA30: 297526.14 | AD30: 7195.99 | AE30: 10633.19 | AF30: 10374 | AG30: 259.19 | AH30: 28019.59 | AI30: 97861.98 | AJ30: 53556.11 | AK30: 51870 | AL30: 124488 | AM30: 1686.11 | AN30: 1 | AO30: 1
A31: 5212 | B31: Other Income - Trash Reimbursements | C31: 10610.51 | D31: 10374 | E31: 236.51 | F31: 0.022798342 | G31: This reflects residents being billed $35 for valet trash. | H31: 64166.62 | I31: 62244 | J31: 1922.62 | K31: 0.030888439 | O31: 2028.99 | S31: 6508.2 | T31: 1492779.8 | U31: 1453480.7 | V31: 21022.28 | W31: 28454.4 | Y31: 4 | Z31: 301371.65 | AA31: 297526.14 | AD31: 2028.99 | AE31: 2241.37 | AF31: 2371.2 | AG31: -129.83 | AH31: 6508.2 | AI31: 21022.28 | AJ31: 11274.76 | AK31: 11856 | AL31: 28454.4 | AM31: -581.24 | AN31: 1 | AO31: 1
A32: 5220 | B32: Other Income - Pest Control Reimbursement | C32: 2236.77 | D32: 2371.2 | E32: -134.43 | F32: -0.056692814 | G32: This reflects income for the pest control fee charge at $9 per month for new residents and all renewals. | H32: 13511.53 | I32: 14227.2 | J32: -715.67 | K32: -0.050302941 | O32: 1941.24 | S32: 7540.32 | T32: 1492779.8 | U32: 1453480.7 | V32: 25398.14 | W32: 35568 | Y32: 4 | Z32: 301371.65 | AA32: 297526.14 | AD32: 1941.24 | AE32: 2962.51 | AF32: 2964 | AG32: -1.49 | AH32: 7540.32 | AI32: 25398.14 | AJ32: 14490.31 | AK32: 14820 | AL32: 35568 | AM32: -329.69 | AN32: 1 | AO32: 1
A33: 5804 | B33: Other Income - Amenity Fee | C33: 3020.08 | D33: 2964 | E33: 56.08 | F33: 0.018920378 | G33: This reflects income for the Amenity fee charge back at $12 per month for new residents and all renewals | H33: 17510.39 | I33: 17784 | J33: -273.61 | K33: -0.015385178 | O33: 2500 | S33: 11050 | T33: 1492779.8 | U33: 1453480.7 | V33: 32450 | W33: 33000 | Y33: 4 | Z33: 301371.65 | AA33: 297526.14 | AD33: 2500 | AE33: 3250 | AF33: 2750 | AG33: 500 | AH33: 11050 | AI33: 32450 | AJ33: 18650 | AK33: 13750 | AL33: 33000 | AM33: 4900 | AN33: 1 | AO33: 1
A34: 5805 | B34: Other Income - Late Charges | C34: 3650 | D34: 2750 | E34: 900 | F34: 0.32727273 | G34: This reflects late fees for the month based on the lease which is $50 on the 6th of the month. | H34: 22300 | I34: 16500 | J34: 5800 | K34: 0.35151515 | O34: 0 | S34: 0 | T34: 1492779.8 | U34: 1453480.7 | V34: 477.67 | W34: 2400 | Y34: 4 | Z34: 301371.65 | AA34: 297526.14 | AD34: 0 | AE34: 0 | AF34: 600 | AG34: -600 | AH34: 0 | AI34: 477.67 | AJ34: 0 | AK34: 1200 | AL34: 2400 | AM34: -1200 | AN34: 1 | AO34: 1
A35: 5810 | B35: Other Income - Laundry Income | C35: 0 | D35: 0 | E35: 0 | F35: 0 | H35: 0 | I35: 1200 | J35: -1200 | K35: -1 | O35: 1726.11 | S35: 6780.25 | T35: 1492779.8 | U35: 1453480.7 | V35: 22449.33 | W35: 32011.2 | Y35: 4 | Z35: 301371.65 | AA35: 297526.14 | AD35: 1726.11 | AE35: 2601.93 | AF35: 2667.6 | AG35: -65.67 | AH35: 6780.25 | AI35: 22449.33 | AJ35: 12848.39 | AK35: 13338 | AL35: 32011.2 | AM35: -489.61 | AN35: 1 | AO35: 1
A36: 5860 | B36: Other Income - Parcel Services Income | C36: 2628.41 | D36: 2667.6 | E36: -39.19 | F36: -0.014691108 | H36: 15476.8 | I36: 16005.6 | J36: -528.8 | K36: -0.033038437 | O36: 681.55 | S36: 1061.16 | T36: 1492779.8 | U36: 1453480.7 | V36: 19808.67 | W36: 44382 | Y36: 4 | Z36: 301371.65 | AA36: 297526.14 | AD36: 681.55 | AE36: 6680.23 | AF36: 3436 | AG36: 3244.23 | AH36: 1061.16 | AI36: 19808.67 | AJ36: 28467.89 | AK36: 15430 | AL36: 44382 | AM36: 13037.89 | AN36: 1 | AO36: 1
A37: 5861 | B37: Other Income - Lease Lock | C37: 7024.97 | D37: 3611 | E37: 3413.97 | F37: 0.94543617 | H37: 35492.86 | I37: 19041 | J37: 16451.86 | K37: 0.8640229 | O37: 0 | S37: 1930 | T37: 1492779.8 | U37: 1453480.7 | V37: 3105.01 | W37: 3490.5 | Y37: 4 | Z37: 301371.65 | AA37: 297526.14 | AD37: 0 | AE37: 415 | AF37: 223.75 | AG37: 191.25 | AH37: 1930 | AI37: 3105.01 | AJ37: 1712.12 | AK37: 671.25 | AL37: 3490.5 | AM37: 1040.87 | AN37: 1 | AO37: 1
A38: 5890 | B38: Other Income - Miscellaneous Income | C38: 536.85 | D38: 268.5 | E38: 268.35 | F38: 0.99944134 | G38: This reflects charges for three residents signed up for Rent Plus at $8.95 per resident and the pest control/bed bug charge back for apartment 244. | H38: 2248.97 | I38: 939.75 | J38: 1309.22 | K38: 1.3931578 | O38: 375 | S38: 1365 | T38: 1492779.8 | U38: 1453480.7 | V38: 4290 | W38: 2100 | Y38: 4 | Z38: 301371.65 | AA38: 297526.14 | AD38: 375 | AE38: 75 | AF38: 225 | AG38: -150 | AH38: 1365 | AI38: 4290 | AJ38: 2400 | AK38: 900 | AL38: 2100 | AM38: 1500 | AN38: 1 | AO38: 1
A39: 5891 | B39: Other Income - NSF Charges | C39: 150 | D39: 225 | E39: -75 | F39: -0.33333333 | G39: This reflects the posting of two NSF fees at $75 each. | H39: 2550 | I39: 1125 | J39: 1425 | K39: 1.2666667 | O39: 1310 | S39: 2170 | T39: 1492779.8 | U39: 1453480.7 | V39: 7907.63 | W39: 3200 | Y39: 4 | Z39: 301371.65 | AA39: 297526.14 | AD39: 1310 | AE39: 1200 | AF39: 400 | AG39: 800 | AH39: 2170 | AI39: 7907.63 | AJ39: 5879.4 | AK39: 1200 | AL39: 3200 | AM39: 4679.4 | AN39: 1 | AO39: 1
A40: 5892 | B40: Other Income - Non-Refundable Pet Fee | C40: 2400 | D40: 400 | E40: 2000 | F40: 5 | G40: This reflects six pet fee charges at $400.00. | H40: 8279.4 | I40: 1600 | J40: 6679.4 | K40: 4.174625 | O40: 1188.37 | S40: 6924.12 | T40: 1492779.8 | U40: 1453480.7 | V40: 15786.43 | W40: 15000 | Y40: 4 | Z40: 301371.65 | AA40: 297526.14 | AD40: 1188.37 | AE40: 3075.88 | AF40: 1250 | AG40: 1825.88 | AH40: 6924.12 | AI40: 15786.43 | AJ40: 12329.97 | AK40: 6250 | AL40: 15000 | AM40: 6079.97 | AN40: 1 | AO40: 1
A41: 5893 | B41: Other Income - Damages | C41: 2159.95 | D41: 1250 | E41: 909.95 | F41: 0.72796 | G41: This reflects collected move-out damages. | H41: 14489.92 | I41: 7500 | J41: 6989.92 | K41: 0.93198933 | O41: 1450 | S41: 6950 | T41: 1492779.8 | U41: 1453480.7 | V41: 16020 | W41: 16750 | Y41: 4 | Z41: 301371.65 | AA41: 297526.14 | AD41: 1450 | AE41: 2000 | AF41: 1450 | AG41: 550 | AH41: 6950 | AI41: 16020 | AJ41: 6075 | AK41: 6950 | AL41: 16750 | AM41: -875 | AN41: 1 | AO41: 1
A42: 5896 | B42: Other Income - Application Fee | C42: 2100 | D42: 1500 | E42: 600 | F42: 0.4 | G42: This reflects twenty-eight paid application fees at $75.00. | H42: 8175 | I42: 8450 | J42: -275 | K42: -0.032544379 | O42: 550 | S42: 3300 | T42: 1492779.8 | U42: 1453480.7 | V42: 8050 | W42: 6000 | Y42: 4 | Z42: 301371.65 | AA42: 297526.14 | AD42: 550 | AE42: 1050 | AF42: 500 | AG42: 550 | AH42: 3300 | AI42: 8050 | AJ42: 3550 | AK42: 2500 | AL42: 6000 | AM42: 1050 | AN42: 1 | AO42: 1
...

Sheet Teagen - CRES
A1: 2024 Actuals | B1: ='Teagen - Input'!C7 -> Jan 2024 | C1: ='Teagen - Input'!D7 -> Feb 2024 | D1: ='Teagen - Input'!E7 -> Mar 2024 | E1: ='Teagen - Input'!F7 -> Apr 2024 | F1: ='Teagen - Input'!G7 -> May 2024 | G1: ='Teagen - Input'!H7 -> Jun 2024 | H1: ='Teagen - Input'!I7 -> Jul 2024 | I1: ='Teagen - Input'!J7 -> Aug 2024 | ... M1: ='Teagen - Input'!N7 -> Dec 2024 | N1: YTD | P1: 1000
A2: Property Asking Rent | B2: =SUMIFS('Teagen - Input'!C:C,'Teagen - Input'!$AH:$AH,'Teagen - CRES'!$A2)/$P$1 -> 275.63379 | C2: =SUMIFS('Teagen - Input'!D:D,'Teagen - Input'!$AH:$AH,'Teagen - CRES'!$A2)/$P$1 -> 275.67173 | D2: =SUMIFS('Teagen - Input'!E:E,'Teagen - Input'!$AH:$AH,'Teagen - CRES'!$A2)/$P$1 -> 279.63521 | E2: =SUMIFS('Teagen - Input'!F:F,'Teagen - Input'!$AH:$AH,'Teagen - CRES'!$A2)/$P$1 -> 278.83564 | F2: =SUMIFS('Teagen - Input'!G:G,'Teagen - Input'!$AH:$AH,'Teagen - CRES'!$A2)/$P$1 -> 275.54436 | G2: =SUMIFS('Teagen - Input'!H:H,'Teagen - Input'!$AH:$AH,'Teagen - CRES'!$A2)/$P$1 -> 275.95953 | H2: =SUMIFS('Teagen - Input'!I:I,'Teagen - Input'!$AH:$AH,'Teagen - CRES'!$A2)/$P$1 -> 276.40572 | I2: =SUMIFS('Teagen - Input'!J:J,'Teagen - Input'!$AH:$AH,'Teagen - CRES'!$A2)/$P$1 -> 274.40638 | J2: =SUMIFS('Teagen - Input'!K:K,'Teagen - Input'!$AH:$AH,'Teagen - CRES'!$A2)/$P$1 -> 274.77606 | K2: =SUMIFS('Teagen - Input'!L:L,'Teagen - Input'!$AH:$AH,'Teagen - CRES'!$A2)/$P$1 -> 275.16013 | L2: =SUMIFS('Teagen - Input'!M:M,'Teagen - Input'!$AH:$AH,'Teagen - CRES'!$A2)/$P$1 -> 267.20342 | M2: =SUMIFS('Teagen - Input'!N:N,'Teagen - Input'!$AH:$AH,'Teagen - CRES'!$A2)/$P$1 -> 268.85527 | N2: =SUM(B2:M2) -> 3298.0872
A3: Loss to lease | B3: =SUMIFS('Teagen - Input'!C:C,'Teagen - Input'!$AH:$AH,'Teagen - CRES'!$A3)/$P$1 -> -20.70322 | C3: =SUMIFS('Teagen - Input'!D:D,'Teagen - Input'!$AH:$AH,'Teagen - CRES'!$A3)/$P$1 -> -18.6667 | D3: =SUMIFS('Teagen - Input'!E:E,'Teagen - Input'!$AH:$AH,'Teagen - CRES'!$A3)/$P$1 -> -21.24726 | E3: =SUMIFS('Teagen - Input'!F:F,'Teagen - Input'!$AH:$AH,'Teagen - CRES'!$A3)/$P$1 -> -18.60865 | F3: =SUMIFS('Teagen - Input'!G:G,'Teagen - Input'!$AH:$AH,'Teagen - CRES'!$A3)/$P$1 -> -16.89225 | G3: =SUMIFS('Teagen - Input'!H:H,'Teagen - Input'!$AH:$AH,'Teagen - CRES'!$A3)/$P$1 -> -17.79909 | H3: =SUMIFS('Teagen - Input'!I:I,'Teagen - Input'!$AH:$AH,'Teagen - CRES'!$A3)/$P$1 -> -18.06564 | I3: =SUMIFS('Teagen - Input'!J:J,'Teagen - Input'!$AH:$AH,'Teagen - CRES'!$A3)/$P$1 -> -16.17815 | J3: =SUMIFS('Teagen - Input'!K:K,'Teagen - Input'!$AH:$AH,'Teagen - CRES'!$A3)/$P$1 -> -14.46973 | K3: =SUMIFS('Teagen - Input'!L:L,'Teagen - Input'!$AH:$AH,'Teagen - CRES'!$A3)/$P$1 -> -15.89083 | L3: =SUMIFS('Teagen - Input'!M:M,'Teagen - Input'!$AH:$AH,'Teagen - CRES'!$A3)/$P$1 -> -8.27196 | M3: =SUMIFS('Teagen - Input'!N:N,'Teagen - Input'!$AH:$AH,'Teagen - CRES'!$A3)/$P$1 -> -9.5042 | N3: =SUM(B3:M3) -> -196.29768
A4: Gross Scheduled Rent | B4: =SUM(B2:B3) -> 254.93057 | C4: =SUM(C2:C3) -> 257.00503 | D4: =SUM(D2:D3) -> 258.38795 | E4: =SUM(E2:E3) -> 260.22699 | F4: =SUM(F2:F3) -> 258.65211 | G4: =SUM(G2:G3) -> 258.16044 | H4: =SUM(H2:H3) -> 258.34008 | I4: =SUM(I2:I3) -> 258.22823 | ... M4: =SUM(M2:M3) -> 259.35107 | N4: =SUM(B4:M4) -> 3101.7896
